Workbook

Sheet Read Me First
B2: Azure Chat Bot Project — AWS Rebuild Tracker
B3: Project re-scoped to AWS. Updated column set + milestone guide below.
B5: 1. What changed
B6: Platform pivot | C6: Customer has moved this from Azure to AWS. The project restarts from access provisioning — the milestone list below reflects an AWS build, not the original Azure one.
B7: New columns added | C7: Phase, Priority, Status, and % Complete have been added to the original 9. This gives the dashboard enough structure to group by phase and show real progress bars, and makes the sheet easy for a Python script to parse later.
B9: 2. The 12 columns, explained
B10: SN | C10: Row order. Keep the sheet sorted by Target Date and this stays meaningful.
B11: Milestone | C11: Name the outcome, not the activity — "AWS account access provisioned" rather than "Setting up AWS access".
B12: Phase | C12: Which stage of delivery this belongs to. Pick from the dropdown (Access & Governance / Infra Build / Bot Platform / Dev / Testing / Security / UAT / Deployment / Handover). This is what lets the dashboard show phase-wise progress.
B13: Task Owner | C13: Person on your team accountable for this milestone. One name per row.
B14: Customer Owner | C14: Counterpart on the customer side who needs to act, approve, or provide input.
B15: Priority | C15: High / Medium / Low — use the dropdown. Helps you and management see what to focus on if something slips.
B16: Start Date | C16: Date work actually starts. Leave blank until it does.
B17: Target Date | C17: The date you're committing to. Fill this in up front for every milestone — the dashboard timeline is built from this.
B18: Actual Date | C18: Date it was actually completed. Leave blank until done.
B19: Status | C19: Use the dropdown: Not Started / In Progress / Completed / Blocked / Delayed. Keep this current — it's the main field the dashboard reads.
B20: % Complete | C20: A number 0–100. For milestones that are one clean deliverable, this will mostly jump from 0 to 100 — that's fine. Use partial numbers for longer-running items like development or testing.
B21: Reason for Delay | C21: Only fill in when Target Date has passed without an Actual Date, or the milestone finished late. One factual sentence is enough.
B23: 3. Weekly habit (5 minutes)
B24: Before your status meeting | C24: Update Status and % Complete for anything that moved, and fill in Actual Date for anything finished. That's all the dashboard needs.
B25: If a date will slip | C25: Only change Target Date if the milestone hasn't started and you're genuinely re-planning. If it's already overdue, leave Target Date as-is and add a Reason for Delay instead.
B27: 4. For the Python app (later)
B28: Keep headers exactly as-is | C28: Column headers are on row 1 of the Tracker tab. Don't rename or reorder them — your script (and the dashboard's import) will match columns by header name.
B29: Use the dropdowns | C29: Status, Phase, and Priority are restricted to fixed lists (data validation) so the values your script sees are always consistent — no "in progress" vs "In-Progress" mismatches.
B31: 5. Alternate-day sync rhythm
B32: Tracker tab = milestone level | C32: Only update Status / % Complete / Last Updated when something genuinely changed. Most milestones won't move every single sync — that's normal.
B33: Sync Log tab = day-to-day | C33: Use this for the actual conversation each sync — quick updates, blockers, next steps. Keeps the Tracker tab clean for management reporting.
B34: Stale-row flag | C34: Any milestone whose "Last Updated" is more than 6 days old (about 3 syncs) gets highlighted amber on the Tracker tab — a quick way to spot what's being overlooked.
B36: 6. Two-level tracking: Milestones vs Sub-Tasks
B37: Tracker tab | C37: Your 18 high-level milestones (1-2 weeks each). This is what management sees.
B38: Sub-Tasks tab | C38: Break each milestone into the day-to-day tasks your team is actually doing. Pick the parent Milestone from the dropdown in column A so it links back correctly.
B39: % Complete is now automatic | C39: The Tracker's % Complete column is now a formula — it counts how many Sub-Tasks under that milestone are marked "Completed" out of the total. Check off sub-tasks as you go, and the milestone-level % updates itself. Don't type into that column anymore — it will get overwritten by the formula.
B40: Status stays manual | C40: Keep setting Status on the Tracker tab yourself (Not Started / In Progress / Completed / Blocked / Delayed) — % Complete alone doesn't tell you if something is blocked.
B42: 7. New tabs added
B43: Executive Summary | C43: A one-page, Excel-native snapshot (KPIs + charts) auto-calculated from the Tracker. Handy if you need to share a quick status without opening the web dashboard.
B44: Risk-Issue Log | C44: Track things that could go wrong (Risks) or already have (Issues), separate from day-to-day delay reasons. Review this briefly at each sync.
B45: Stakeholders | C45: One place for who's who — your team and the customer's — and their RACI role. Fill this in early; it'll save you time later.
B46: Change Log | C46: A short history of major changes (like the Azure→AWS platform switch already logged as the first entry). Add an entry whenever scope or a committed date genuinely changes.
B48: 8. RAG Status & Remarks columns
B49: RAG Status (auto) | C49: Calculated for you — Green (on track / completed on time), Amber (completed late, or due within 7 days), Red (overdue, or marked Blocked). Shows "-" until a Target Date is set. Don't type into this column — it's a formula.
...

Sheet Executive Summary
A1: Azure Chat Bot (AWS Rebuild) — Executive Summary
A2: Auto-calculated from the Tracker tab. Refresh (F9) after updating milestone data.
A4: Total Milestones | B4: =SUMPRODUCT((Tracker!$B$2:$B$35<>"")*1) -> 18
A5: Completed | B5: =COUNTIF(Tracker!$J$2:$J$35,"Completed") -> 0
A6: Overdue | B6: =SUMPRODUCT((Tracker!$H$2:$H$35<>"")*(Tracker!$H$2:$H$35<TODAY())*(Tracker!$I$2:$I$35="")*(Tracker!$J$2:$J$35<>"Completed")) -> 0
A7: Due Soon (7 days) | B7: =SUMPRODUCT((Tracker!$H$2:$H$35<>"")*(Tracker!$H$2:$H$35>=TODAY())*(Tracker!$H$2:$H$35<=TODAY()+7)*(Tracker!$I$2:$I$35="")*(Tracker!$J$2:$J$35<>"Completed")) -> 0
A9: Overall % Complete | B9: =IFERROR(ROUND(AVERAGE(Tracker!$K$2:$K$35),0),0) -> 25
A12: Status Breakdown | D12: Phase-wise Avg. % Complete
A13: Status | B13: Count | D13: Phase | E13: Avg %
A14: Not Started | B14: =COUNTIF(Tracker!$J$2:$J$35,"Not Started") -> 18 | D14: Access & Governance | E14: =IFERROR(ROUND(AVERAGEIFS(Tracker!$K$2:$K$35,Tracker!$C$2:$C$35,"Access & Governance"),0),0) -> 25
A15: In Progress | B15: =COUNTIF(Tracker!$J$2:$J$35,"In Progress") -> 0 | D15: Infra Build | E15: =IFERROR(ROUND(AVERAGEIFS(Tracker!$K$2:$K$35,Tracker!$C$2:$C$35,"Infra Build"),0),0) -> 0
A16: Completed | B16: =COUNTIF(Tracker!$J$2:$J$35,"Completed") -> 0 | D16: Bot Platform | E16: =IFERROR(ROUND(AVERAGEIFS(Tracker!$K$2:$K$35,Tracker!$C$2:$C$35,"Bot Platform"),0),0) -> 0
A17: Blocked | B17: =COUNTIF(Tracker!$J$2:$J$35,"Blocked") -> 0 | D17: Development | E17: =IFERROR(ROUND(AVERAGEIFS(Tracker!$K$2:$K$35,Tracker!$C$2:$C$35,"Development"),0),0) -> 0
A18: Delayed | B18: =COUNTIF(Tracker!$J$2:$J$35,"Delayed") -> 0 | D18: Testing | E18: =IFERROR(ROUND(AVERAGEIFS(Tracker!$K$2:$K$35,Tracker!$C$2:$C$35,"Testing"),0),0) -> 0
D19: Security | E19: =IFERROR(ROUND(AVERAGEIFS(Tracker!$K$2:$K$35,Tracker!$C$2:$C$35,"Security"),0),0) -> 0
D20: UAT | E20: =IFERROR(ROUND(AVERAGEIFS(Tracker!$K$2:$K$35,Tracker!$C$2:$C$35,"UAT"),0),0) -> 0
D21: Deployment | E21: =IFERROR(ROUND(AVERAGEIFS(Tracker!$K$2:$K$35,Tracker!$C$2:$C$35,"Deployment"),0),0) -> 0
D22: Handover | E22: =IFERROR(ROUND(AVERAGEIFS(Tracker!$K$2:$K$35,Tracker!$C$2:$C$35,"Handover"),0),0) -> 0
A80: Helper Data — auto-calculated, feeds the charts above. Don't edit.
A82: RAG | B82: Count | D82: Priority | E82: Count | G82: Risk Impact (Open) | H82: Count | J82: Segment | K82: Value
A83: Green | B83: =COUNTIFS(Tracker!$B$2:$B$35,"<>",Tracker!$N$2:$N$35,"Green") -> 18 | D83: High | E83: =COUNTIF(Tracker!$F$2:$F$35,"High") -> 13 | G83: High | H83: =COUNTIFS('Risk-Issue Log'!$E$2:$E$33,"High",'Risk-Issue Log'!$I$2:$I$33,"Open") -> 1 | J83: Complete | K83: =$B$9 -> 25
A84: Amber | B84: =COUNTIFS(Tracker!$B$2:$B$35,"<>",Tracker!$N$2:$N$35,"Amber") -> 0 | D84: Medium | E84: =COUNTIF(Tracker!$F$2:$F$35,"Medium") -> 5 | G84: Medium | H84: =COUNTIFS('Risk-Issue Log'!$E$2:$E$33,"Medium",'Risk-Issue Log'!$I$2:$I$33,"Open") -> 1 | J84: Remaining | K84: =100-$B$9 -> 75
A85: Red | B85: =COUNTIFS(Tracker!$B$2:$B$35,"<>",Tracker!$N$2:$N$35,"Red") -> 0 | D85: Low | E85: =COUNTIF(Tracker!$F$2:$F$35,"Low") -> 0 | G85: Low | H85: =COUNTIFS('Risk-Issue Log'!$E$2:$E$33,"Low",'Risk-Issue Log'!$I$2:$I$33,"Open") -> 0
A89: Phase | B89: Count | D89: Owner | E89: Count
A90: Access & Governance | B90: =COUNTIF(Tracker!$C$2:$C$35,"Access & Governance") -> 2 | D90: =IF(Stakeholders!$A$2="","",Stakeholders!$A$2) -> Priya Sharma | E90: =IF(Stakeholders!$A$2="","",COUNTIF(Tracker!$D$2:$D$35,Stakeholders!$A$2)) -> 0
A91: Infra Build | B91: =COUNTIF(Tracker!$C$2:$C$35,"Infra Build") -> 3 | D91: =IF(Stakeholders!$A$3="","",Stakeholders!$A$3) -> Arjun Mehta | E91: =IF(Stakeholders!$A$3="","",COUNTIF(Tracker!$D$2:$D$35,Stakeholders!$A$3)) -> 0
A92: Bot Platform | B92: =COUNTIF(Tracker!$C$2:$C$35,"Bot Platform") -> 3 | D92: =IF(Stakeholders!$A$4="","",Stakeholders!$A$4) | E92: =IF(Stakeholders!$A$4="","",COUNTIF(Tracker!$D$2:$D$35,Stakeholders!$A$4))
A93: Development | B93: =COUNTIF(Tracker!$C$2:$C$35,"Development") -> 3 | D93: =IF(Stakeholders!$A$5="","",Stakeholders!$A$5) | E93: =IF(Stakeholders!$A$5="","",COUNTIF(Tracker!$D$2:$D$35,Stakeholders!$A$5))
A94: Testing | B94: =COUNTIF(Tracker!$C$2:$C$35,"Testing") -> 2 | D94: =IF(Stakeholders!$A$6="","",Stakeholders!$A$6) | E94: =IF(Stakeholders!$A$6="","",COUNTIF(Tracker!$D$2:$D$35,Stakeholders!$A$6))
A95: Security | B95: =COUNTIF(Tracker!$C$2:$C$35,"Security") -> 1 | D95: =IF(Stakeholders!$A$7="","",Stakeholders!$A$7) | E95: =IF(Stakeholders!$A$7="","",COUNTIF(Tracker!$D$2:$D$35,Stakeholders!$A$7))
A96: UAT | B96: =COUNTIF(Tracker!$C$2:$C$35,"UAT") -> 1 | D96: =IF(Stakeholders!$A$8="","",Stakeholders!$A$8) | E96: =IF(Stakeholders!$A$8="","",COUNTIF(Tracker!$D$2:$D$35,Stakeholders!$A$8))
A97: Deployment | B97: =COUNTIF(Tracker!$C$2:$C$35,"Deployment") -> 2 | D97: =IF(Stakeholders!$A$9="","",Stakeholders!$A$9) | E97: =IF(Stakeholders!$A$9="","",COUNTIF(Tracker!$D$2:$D$35,Stakeholders!$A$9))
A98: Handover | B98: =COUNTIF(Tracker!$C$2:$C$35,"Handover") -> 1 | D98: =IF(Stakeholders!$A$10="","",Stakeholders!$A$10) | E98: =IF(Stakeholders!$A$10="","",COUNTIF(Tracker!$D$2:$D$35,Stakeholders!$A$10))
D99: =IF(Stakeholders!$A$11="","",Stakeholders!$A$11) | E99: =IF(Stakeholders!$A$11="","",COUNTIF(Tracker!$D$2:$D$35,Stakeholders!$A$11))
D100: Unassigned | E100: =COUNTIFS(Tracker!$B$2:$B$35,"<>",Tracker!$D$2:$D$35,"") -> 18

Sheet Tracker
A1: SN | B1: Milestone | C1: Phase | D1: Task Owner | E1: Customer Owner | F1: Priority | G1: Start Date | H1: Target Date | I1: Actual Date | J1: Status | K1: % Complete | L1: Reason for Delay | M1: Last Updated | N1: RAG Status | O1: Remarks / Next Steps
A2: 1 | B2: AWS Landing Zone / Account Access Provisioned | C2: Access & Governance | F2: High | H2: 46218 | J2: Not Started | K2: =IF(COUNTIF('Sub-Tasks'!$A$2:$A$200,$B2)=0,"",ROUND(COUNTIFS('Sub-Tasks'!$A$2:$A$200,$B2,'Sub-Tasks'!$F$2:$F$200,"Completed")/COUNTIF('Sub-Tasks'!$A$2:$A$200,$B2)*100,0)) -> 50 | N2: =IF($J2="Blocked","Red",IF($I2<>"",IF(OR($H2="",$I2<=$H2),"Green","Amber"),IF($H2="","-",IF($H2<TODAY(),"Red",IF($H2<=TODAY()+7,"Amber","Green"))))) -> Green
A3: 2 | B3: IAM Roles, Policies & Access Controls Setup | C3: Access & Governance | F3: High | H3: 46225 | J3: Not Started | K3: =IF(COUNTIF('Sub-Tasks'!$A$2:$A$200,$B3)=0,"",ROUND(COUNTIFS('Sub-Tasks'!$A$2:$A$200,$B3,'Sub-Tasks'!$F$2:$F$200,"Completed")/COUNTIF('Sub-Tasks'!$A$2:$A$200,$B3)*100,0)) -> 0 | N3: =IF($J3="Blocked","Red",IF($I3<>"",IF(OR($H3="",$I3<=$H3),"Green","Amber"),IF($H3="","-",IF($H3<TODAY(),"Red",IF($H3<=TODAY()+7,"Amber","Green"))))) -> Green
A4: 3 | B4: VPC & Networking Setup | C4: Infra Build | F4: High | H4: 46239 | J4: Not Started | K4: =IF(COUNTIF('Sub-Tasks'!$A$2:$A$200,$B4)=0,"",ROUND(COUNTIFS('Sub-Tasks'!$A$2:$A$200,$B4,'Sub-Tasks'!$F$2:$F$200,"Completed")/COUNTIF('Sub-Tasks'!$A$2:$A$200,$B4)*100,0)) | N4: =IF($J4="Blocked","Red",IF($I4<>"",IF(OR($H4="",$I4<=$H4),"Green","Amber"),IF($H4="","-",IF($H4<TODAY(),"Red",IF($H4<=TODAY()+7,"Amber","Green"))))) -> Green
A5: 4 | B5: Core AWS Services Provisioning (Compute, Storage, DB) | C5: Infra Build | F5: High | H5: 46253 | J5: Not Started | K5: =IF(COUNTIF('Sub-Tasks'!$A$2:$A$200,$B5)=0,"",ROUND(COUNTIFS('Sub-Tasks'!$A$2:$A$200,$B5,'Sub-Tasks'!$F$2:$F$200,"Completed")/COUNTIF('Sub-Tasks'!$A$2:$A$200,$B5)*100,0)) | N5: =IF($J5="Blocked","Red",IF($I5<>"",IF(OR($H5="",$I5<=$H5),"Green","Amber"),IF($H5="","-",IF($H5<TODAY(),"Red",IF($H5<=TODAY()+7,"Amber","Green"))))) -> Green
A6: 5 | B6: CI/CD Pipeline Setup | C6: Infra Build | F6: Medium | H6: 46262 | J6: Not Started | K6: =IF(COUNTIF('Sub-Tasks'!$A$2:$A$200,$B6)=0,"",ROUND(COUNTIFS('Sub-Tasks'!$A$2:$A$200,$B6,'Sub-Tasks'!$F$2:$F$200,"Completed")/COUNTIF('Sub-Tasks'!$A$2:$A$200,$B6)*100,0)) | N6: =IF($J6="Blocked","Red",IF($I6<>"",IF(OR($H6="",$I6<=$H6),"Green","Amber"),IF($H6="","-",IF($H6<TODAY(),"Red",IF($H6<=TODAY()+7,"Amber","Green"))))) -> Green
A7: 6 | B7: Bot Platform Setup (Amazon Lex / Bedrock Agent) | C7: Bot Platform | F7: High | H7: 46276 | J7: Not Started | K7: =IF(COUNTIF('Sub-Tasks'!$A$2:$A$200,$B7)=0,"",ROUND(COUNTIFS('Sub-Tasks'!$A$2:$A$200,$B7,'Sub-Tasks'!$F$2:$F$200,"Completed")/COUNTIF('Sub-Tasks'!$A$2:$A$200,$B7)*100,0)) | N7: =IF($J7="Blocked","Red",IF($I7<>"",IF(OR($H7="",$I7<=$H7),"Green","Amber"),IF($H7="","-",IF($H7<TODAY(),"Red",IF($H7<=TODAY()+7,"Amber","Green"))))) -> Green
A8: 7 | B8: Conversation Design (Intents & Flows) | C8: Bot Platform | F8: High | H8: 46283 | J8: Not Started | K8: =IF(COUNTIF('Sub-Tasks'!$A$2:$A$200,$B8)=0,"",ROUND(COUNTIFS('Sub-Tasks'!$A$2:$A$200,$B8,'Sub-Tasks'!$F$2:$F$200,"Completed")/COUNTIF('Sub-Tasks'!$A$2:$A$200,$B8)*100,0)) | N8: =IF($J8="Blocked","Red",IF($I8<>"",IF(OR($H8="",$I8<=$H8),"Green","Amber"),IF($H8="","-",IF($H8<TODAY(),"Red",IF($H8<=TODAY()+7,"Amber","Green"))))) -> Green
A9: 8 | B9: NLU Model Training & Tuning | C9: Bot Platform | F9: Medium | H9: 46295 | J9: Not Started | K9: =IF(COUNTIF('Sub-Tasks'!$A$2:$A$200,$B9)=0,"",ROUND(COUNTIFS('Sub-Tasks'!$A$2:$A$200,$B9,'Sub-Tasks'!$F$2:$F$200,"Completed")/COUNTIF('Sub-Tasks'!$A$2:$A$200,$B9)*100,0)) | N9: =IF($J9="Blocked","Red",IF($I9<>"",IF(OR($H9="",$I9<=$H9),"Green","Amber"),IF($H9="","-",IF($H9<TODAY(),"Red",IF($H9<=TODAY()+7,"Amber","Green"))))) -> Green
A10: 9 | B10: Knowledge Base Integration (Kendra / Bedrock KB) | C10: Development | F10: High | H10: 46309 | J10: Not Started | K10: =IF(COUNTIF('Sub-Tasks'!$A$2:$A$200,$B10)=0,"",ROUND(COUNTIFS('Sub-Tasks'!$A$2:$A$200,$B10,'Sub-Tasks'!$F$2:$F$200,"Completed")/COUNTIF('Sub-Tasks'!$A$2:$A$200,$B10)*100,0)) | N10: =IF($J10="Blocked","Red",IF($I10<>"",IF(OR($H10="",$I10<=$H10),"Green","Amber"),IF($H10="","-",IF($H10<TODAY(),"Red",IF($H10<=TODAY()+7,"Amber","Green"))))) -> Green
A11: 10 | B11: Backend/App Logic Development | C11: Development | F11: High | H11: 46323 | J11: Not Started | K11: =IF(COUNTIF('Sub-Tasks'!$A$2:$A$200,$B11)=0,"",ROUND(COUNTIFS('Sub-Tasks'!$A$2:$A$200,$B11,'Sub-Tasks'!$F$2:$F$200,"Completed")/COUNTIF('Sub-Tasks'!$A$2:$A$200,$B11)*100,0)) | N11: =IF($J11="Blocked","Red",IF($I11<>"",IF(OR($H11="",$I11<=$H11),"Green","Amber"),IF($H11="","-",IF($H11<TODAY(),"Red",IF($H11<=TODAY()+7,"Amber","Green"))))) -> Green
A12: 11 | B12: Channel Integration (Web / Teams / Slack) | C12: Development | F12: Medium | H12: 46332 | J12: Not Started | K12: =IF(COUNTIF('Sub-Tasks'!$A$2:$A$200,$B12)=0,"",ROUND(COUNTIFS('Sub-Tasks'!$A$2:$A$200,$B12,'Sub-Tasks'!$F$2:$F$200,"Completed")/COUNTIF('Sub-Tasks'!$A$2:$A$200,$B12)*100,0)) | N12: =IF($J12="Blocked","Red",IF($I12<>"",IF(OR($H12="",$I12<=$H12),"Green","Amber"),IF($H12="","-",IF($H12<TODAY(),"Red",IF($H12<=TODAY()+7,"Amber","Green"))))) -> Green
A13: 12 | B13: Internal QA & Functional Testing | C13: Testing | F13: High | H13: 46344 | J13: Not Started | K13: =IF(COUNTIF('Sub-Tasks'!$A$2:$A$200,$B13)=0,"",ROUND(COUNTIFS('Sub-Tasks'!$A$2:$A$200,$B13,'Sub-Tasks'!$F$2:$F$200,"Completed")/COUNTIF('Sub-Tasks'!$A$2:$A$200,$B13)*100,0)) | N13: =IF($J13="Blocked","Red",IF($I13<>"",IF(OR($H13="",$I13<=$H13),"Green","Amber"),IF($H13="","-",IF($H13<TODAY(),"Red",IF($H13<=TODAY()+7,"Amber","Green"))))) -> Green
... A19: 18 | B19: Hypercare, Documentation & Handover | C19: Handover | F19: Medium | H19: 46407 | J19: Not Started | K19: =IF(COUNTIF('Sub-Tasks'!$A$2:$A$200,$B19)=0,"",ROUND(COUNTIFS('Sub-Tasks'!$A$2:$A$200,$B19,'Sub-Tasks'!$F$2:$F$200,"Completed")/COUNTIF('Sub-Tasks'!$A$2:$A$200,$B19)*100,0)) | N19: =IF($J19="Blocked","Red",IF($I19<>"",IF(OR($H19="",$I19<=$H19),"Green","Amber"),IF($H19="","-",IF($H19<TODAY(),"Red",IF($H19<=TODAY()+7,"Amber","Green"))))) -> Green
K20: =IF(COUNTIF('Sub-Tasks'!$A$2:$A$200,$B20)=0,"",ROUND(COUNTIFS('Sub-Tasks'!$A$2:$A$200,$B20,'Sub-Tasks'!$F$2:$F$200,"Completed")/COUNTIF('Sub-Tasks'!$A$2:$A$200,$B20)*100,0)) | N20: =IF($J20="Blocked","Red",IF($I20<>"",IF(OR($H20="",$I20<=$H20),"Green","Amber"),IF($H20="","-",IF($H20<TODAY(),"Red",IF($H20<=TODAY()+7,"Amber","Green"))))) -> -
K21: =IF(COUNTIF('Sub-Tasks'!$A$2:$A$200,$B21)=0,"",ROUND(COUNTIFS('Sub-Tasks'!$A$2:$A$200,$B21,'Sub-Tasks'!$F$2:$F$200,"Completed")/COUNTIF('Sub-Tasks'!$A$2:$A$200,$B21)*100,0)) | N21: =IF($J21="Blocked","Red",IF($I21<>"",IF(OR($H21="",$I21<=$H21),"Green","Amber"),IF($H21="","-",IF($H21<TODAY(),"Red",IF($H21<=TODAY()+7,"Amber","Green"))))) -> -
K22: =IF(COUNTIF('Sub-Tasks'!$A$2:$A$200,$B22)=0,"",ROUND(COUNTIFS('Sub-Tasks'!$A$2:$A$200,$B22,'Sub-Tasks'!$F$2:$F$200,"Completed")/COUNTIF('Sub-Tasks'!$A$2:$A$200,$B22)*100,0)) | N22: =IF($J22="Blocked","Red",IF($I22<>"",IF(OR($H22="",$I22<=$H22),"Green","Amber"),IF($H22="","-",IF($H22<TODAY(),"Red",IF($H22<=TODAY()+7,"Amber","Green"))))) -> -
K23: =IF(COUNTIF('Sub-Tasks'!$A$2:$A$200,$B23)=0,"",ROUND(COUNTIFS('Sub-Tasks'!$A$2:$A$200,$B23,'Sub-Tasks'!$F$2:$F$200,"Completed")/COUNTIF('Sub-Tasks'!$A$2:$A$200,$B23)*100,0)) | N23: =IF($J23="Blocked","Red",IF($I23<>"",IF(OR($H23="",$I23<=$H23),"Green","Amber"),IF($H23="","-",IF($H23<TODAY(),"Red",IF($H23<=TODAY()+7,"Amber","Green"))))) -> -
K24: =IF(COUNTIF('Sub-Tasks'!$A$2:$A$200,$B24)=0,"",ROUND(COUNTIFS('Sub-Tasks'!$A$2:$A$200,$B24,'Sub-Tasks'!$F$2:$F$200,"Completed")/COUNTIF('Sub-Tasks'!$A$2:$A$200,$B24)*100,0)) | N24: =IF($J24="Blocked","Red",IF($I24<>"",IF(OR($H24="",$I24<=$H24),"Green","Amber"),IF($H24="","-",IF($H24<TODAY(),"Red",IF($H24<=TODAY()+7,"Amber","Green"))))) -> -
K25: =IF(COUNTIF('Sub-Tasks'!$A$2:$A$200,$B25)=0,"",ROUND(COUNTIFS('Sub-Tasks'!$A$2:$A$200,$B25,'Sub-Tasks'!$F$2:$F$200,"Completed")/COUNTIF('Sub-Tasks'!$A$2:$A$200,$B25)*100,0)) | N25: =IF($J25="Blocked","Red",IF($I25<>"",IF(OR($H25="",$I25<=$H25),"Green","Amber"),IF($H25="","-",IF($H25<TODAY(),"Red",IF($H25<=TODAY()+7,"Amber","Green"))))) -> -
K26: =IF(COUNTIF('Sub-Tasks'!$A$2:$A$200,$B26)=0,"",ROUND(COUNTIFS('Sub-Tasks'!$A$2:$A$200,$B26,'Sub-Tasks'!$F$2:$F$200,"Completed")/COUNTIF('Sub-Tasks'!$A$2:$A$200,$B26)*100,0)) | N26: =IF($J26="Blocked","Red",IF($I26<>"",IF(OR($H26="",$I26<=$H26),"Green","Amber"),IF($H26="","-",IF($H26<TODAY(),"Red",IF($H26<=TODAY()+7,"Amber","Green"))))) -> -
K27: =IF(COUNTIF('Sub-Tasks'!$A$2:$A$200,$B27)=0,"",ROUND(COUNTIFS('Sub-Tasks'!$A$2:$A$200,$B27,'Sub-Tasks'!$F$2:$F$200,"Completed")/COUNTIF('Sub-Tasks'!$A$2:$A$200,$B27)*100,0)) | N27: =IF($J27="Blocked","Red",IF($I27<>"",IF(OR($H27="",$I27<=$H27),"Green","Amber"),IF($H27="","-",IF($H27<TODAY(),"Red",IF($H27<=TODAY()+7,"Amber","Green"))))) -> -
K28: =IF(COUNTIF('Sub-Tasks'!$A$2:$A$200,$B28)=0,"",ROUND(COUNTIFS('Sub-Tasks'!$A$2:$A$200,$B28,'Sub-Tasks'!$F$2:$F$200,"Completed")/COUNTIF('Sub-Tasks'!$A$2:$A$200,$B28)*100,0)) | N28: =IF($J28="Blocked","Red",IF($I28<>"",IF(OR($H28="",$I28<=$H28),"Green","Amber"),IF($H28="","-",IF($H28<TODAY(),"Red",IF($H28<=TODAY()+7,"Amber","Green"))))) -> -
K29: =IF(COUNTIF('Sub-Tasks'!$A$2:$A$200,$B29)=0,"",ROUND(COUNTIFS('Sub-Tasks'!$A$2:$A$200,$B29,'Sub-Tasks'!$F$2:$F$200,"Completed")/COUNTIF('Sub-Tasks'!$A$2:$A$200,$B29)*100,0)) | N29: =IF($J29="Blocked","Red",IF($I29<>"",IF(OR($H29="",$I29<=$H29),"Green","Amber"),IF($H29="","-",IF($H29<TODAY(),"Red",IF($H29<=TODAY()+7,"Amber","Green"))))) -> -
K30: =IF(COUNTIF('Sub-Tasks'!$A$2:$A$200,$B30)=0,"",ROUND(COUNTIFS('Sub-Tasks'!$A$2:$A$200,$B30,'Sub-Tasks'!$F$2:$F$200,"Completed")/COUNTIF('Sub-Tasks'!$A$2:$A$200,$B30)*100,0)) | N30: =IF($J30="Blocked","Red",IF($I30<>"",IF(OR($H30="",$I30<=$H30),"Green","Amber"),IF($H30="","-",IF($H30<TODAY(),"Red",IF($H30<=TODAY()+7,"Amber","Green"))))) -> -
K31: =IF(COUNTIF('Sub-Tasks'!$A$2:$A$200,$B31)=0,"",ROUND(COUNTIFS('Sub-Tasks'!$A$2:$A$200,$B31,'Sub-Tasks'!$F$2:$F$200,"Completed")/COUNTIF('Sub-Tasks'!$A$2:$A$200,$B31)*100,0)) | N31: =IF($J31="Blocked","Red",IF($I31<>"",IF(OR($H31="",$I31<=$H31),"Green","Amber"),IF($H31="","-",IF($H31<TODAY(),"Red",IF($H31<=TODAY()+7,"Amber","Green"))))) -> -
... K35: =IF(COUNTIF('Sub-Tasks'!$A$2:$A$200,$B35)=0,"",ROUND(COUNTIFS('Sub-Tasks'!$A$2:$A$200,$B35,'Sub-Tasks'!$F$2:$F$200,"Completed")/COUNTIF('Sub-Tasks'!$A$2:$A$200,$B35)*100,0)) | N35: =IF($J35="Blocked","Red",IF($I35<>"",IF(OR($H35="",$I35<=$H35),"Green","Amber"),IF($H35="","-",IF($H35<TODAY(),"Red",IF($H35<=TODAY()+7,"Amber","Green"))))) -> -

Sheet Sync Log
A1: Date | B1: Milestone / Workstream | C1: Update Owner | D1: Key Update | E1: Blockers / Issues | F1: Next Steps | G1: Next Sync Date
A44: Tip: log the highlights from each alternate-day sync here. Update Status/% Complete on the Tracker tab only when something actually changed.

Sheet Sub-Tasks
A1: Milestone | B1: Sub-Task | C1: Owner | D1: Start Date | E1: Target Date | F1: Status | G1: Notes
A2: AWS Landing Zone / Account Access Provisioned | B2: Raise AWS account request with customer | D2: 46213 | E2: 46214 | F2: Completed
A3: AWS Landing Zone / Account Access Provisioned | B3: Confirm billing & org structure | D3: 46214 | E3: 46215 | F3: Completed
A4: AWS Landing Zone / Account Access Provisioned | B4: Set up root account MFA | D4: 46215 | E4: 46216 | F4: In Progress
A5: AWS Landing Zone / Account Access Provisioned | B5: Validate access with team | D5: 46216 | E5: 46218 | F5: Not Started
A6: IAM Roles, Policies & Access Controls Setup | B6: Define role structure (dev/test/prod) | D6: 46219 | E6: 46221 | F6: Not Started
A7: IAM Roles, Policies & Access Controls Setup | B7: Create IAM policies | D7: 46221 | E7: 46223 | F7: Not Started
A8: IAM Roles, Policies & Access Controls Setup | B8: Assign roles to team members | D8: 46223 | E8: 46225 | F8: Not Started

Sheet Risk-Issue Log
A1: ID | B1: Type | C1: Description | D1: Related Milestone | E1: Impact | F1: Likelihood | G1: Mitigation / Action Plan | H1: Owner | I1: Status | J1: Date Raised | K1: Date Resolved
A2: 1 | B2: Risk | C2: AWS access/IAM approvals may take longer than planned due to customer's internal governance process | D2: AWS Landing Zone / Account Access Provisioned | E2: High | F2: Medium | G2: Escalate access requests early; get a named approver on customer side | I2: Open | J2: 46204
A3: 2 | B3: Risk | C3: Bedrock/Lex service limits or region availability may differ from what was used on Azure | D3: Bot Platform Setup (Amazon Lex / Bedrock Agent) | E3: Medium | F3: Medium | G3: Confirm service quotas and region support before design starts | I3: Open | J3: 46204

Sheet Stakeholders
A1: Name | B1: Role / Title | C1: Organization | D1: RACI | E1: Email | F1: Notes
A2: Priya Sharma | B2: Delivery Lead | C2: Ours | D2: Responsible
A3: Arjun Mehta | B3: Cloud/Infra Engineer | C3: Ours | D3: Responsible
B4: Project Sponsor | C4: Customer | D4: Accountable
B5: Customer IT/Security Contact | C5: Customer | D5: Consulted

Sheet Change Log
A1: Date | B1: Milestone | C1: Field Changed | D1: Old Value | E1: New Value | F1: Reason | G1: Changed By
A2: 46204 | B2: All milestones | C2: Scope/Platform | D2: Azure-based build | E2: AWS-based build | F2: Customer requested platform change from Azure to AWS
